Workbook

Sheet ССРСС
A1: "УТВЕРЖДАЮ" | F1: (Внешний файл)
A2: Заместитель директора | F2: Приложение 3 к Техническому заданию
A3: ГАУ "МосжилНИИпроект"
A4: __________________И.А. Клоков
C6: 2026 г.
B8: Сводный сметный расчет в сумме | D8: =H39 -> 66697.21 | E8: руб.
A10: СВОДНЫЙ СМЕТНЫЙ РАСЧЕТ СТОИМОСТИ СТРОИТЕЛЬСТВА
A11: Выполнение работ по капитальному ремонту здания в Басманном районе ЦАО города Москвы
A13: Составлен в текущих ценах по состоянию на 2 квартал 2026 г.
A14: № п/п | B14: Обоснование | C14: Наименование глав, объектов, работ и затрат | D14: Сметная стоимость, тыс.руб.
D15: Строительные работы | E15: Монтажные работы | F15: Оборудование | G15: Прочие | H15: Общая
A16: 1 | B16: 2 | C16: 3 | D16: 4 | E16: 5 | F16: 6 | G16: 7 | H16: 8
A17: Глава 2. Основные объекты строительства, реконструкции, капитального ремонта
A18: 1 | B18: ОСР №02-01 | C18: Выполнение работ по капитальному ремонту | D18: ='ОСР 02-01'!D34 -> 20114.37 | E18: ='ОСР 02-01'!E34 -> 17104.55 | F18: ='ОСР 02-01'!F34 -> 13858.18 | G18: - | H18: =SUM(D18:G18) -> 51077.1
A19: в т.ч. Оборудование , не облагаемое НДС | F19: ='ОСР 02-01'!F33 -> 58.11
A20: Итого по гл. 2 | D20: =D18 -> 20114.37 | E20: =E18 -> 17104.55 | F20: =F18 -> 13858.18 | G20: - | H20: =SUM(D20:G20) -> 51077.1
A21: Итого по гл. 1-7 | D21: =D20 -> 20114.37 | E21: =E20 -> 17104.55 | F21: =F20 -> 13858.18 | G21: - | H21: =SUM(D21:G21) -> 51077.1
A23: Глава 8. Временные здания и сооружения
A24: 2 | B24: МОС.05.05-006.2025 прил. В.3, п. 1.2 | C24: Временные здания и сооружения 1,4% | D24: =D18*0.014 -> 281.6 | E24: =E18*0.014 -> 239.46 | F24: - | G24: - | H24: =SUM(D24:G24) -> 521.06
A25: Итого по гл. 8 | D25: =D24 -> 281.6 | E25: =E24 -> 239.46 | F25: - | G25: - | H25: =SUM(D25:G25) -> 521.06
A26: Итого по гл. 1-8 | D26: =D21+D25 -> 20395.97 | E26: =E21+E25 -> 17344.01 | F26: =F21 -> 13858.18 | G26: - | H26: =SUM(D26:G26) -> 51598.16
A27: Глава 9. Прочие работы и затраты
A28: 3 | B28: ЛС 09-01-01 | C28: Пусконаладочные работы | D28: 0 | E28: 0 | F28: 0 | G28: ='ЛС 09-01-01'!J14 -> 2010 | H28: =SUM(D28:G28) -> 2010
A29: Итого по гл. 9 | D29: =SUM(D28:D28) -> 0 | E29: =SUM(E28:E28) -> 0 | F29: =SUM(F28:F28) -> 0 | G29: =G28 -> 2010 | H29: =SUM(D29:G29) -> 2010
A30: Итого по гл. 1-9 | D30: =D26 -> 20395.97 | E30: =E26 -> 17344.01 | F30: =F26 -> 13858.18 | G30: =G29 -> 2010 | H30: =SUM(D30:G30) -> 53608.16
A31: Итого по гл. 1-12 | D31: =D30 -> 20395.97 | E31: =E30 -> 17344.01 | F31: =F30 -> 13858.18 | G31: =G30 -> 2010 | H31: =SUM(D31:G31) -> 53608.16
A32: Непредвиденные затраты
A33: 4 | B33: ТСН-2001.12 прил.5 п.13.1 | C33: Резерв средств на непредвиденные работы и затраты - 2% | D33: =D31*0.02 -> 407.92 | E33: =E31*0.02 -> 346.88 | F33: =F31*0.02 -> 277.16 | G33: =G31*0.02 -> 40.2 | H33: =SUM(D33:G33) -> 1072.16
A34: Итого непредвиденные затраты | D34: =D33 -> 407.92 | E34: =E33 -> 346.88 | F34: =F33 -> 277.16 | G34: =G33 -> 40.2 | H34: =SUM(D34:G34) -> 1072.16
A35: Итого по сводному сметному расчету без НДС | D35: =D31+D34 -> 20803.89 | E35: =E31+E34 -> 17690.89 | F35: =F31+F34 -> 14135.34 | G35: =G31+G34 -> 2050.2 | H35: =SUM(D35:G35) -> 54680.32
A36: Налоги и обязательные платежи
A37: 5 | B37: ТСН-2001.12 прил.5 п.13.2 | C37: НДС 22% | D37: =D35*0.22 -> 4576.86 | E37: =E35*0.22 -> 3892 | F37: =(F35-F19)*0.22 -> 3096.99 | G37: =G35*0.22 -> 451.04 | H37: =SUM(D37:G37) -> 12016.89
A38: Итого "Налоги и обязательные платежи" | D38: =D37 -> 4576.86 | E38: =E37 -> 3892 | F38: =F37 -> 3096.99 | G38: =G37 -> 451.04 | H38: =SUM(D38:G38) -> 12016.89
A39: Итого по сводному сметному расчету | D39: =D35+D38 -> 25380.75 | E39: =E35+E38 -> 21582.89 | F39: =F35+F38 -> 17232.33 | G39: =G35+G38 -> 2501.24 | H39: =SUM(D39:G39) -> 66697.21
A40: 6 | B40: ТСН-2001.12 прил.5 п.13.3 | C40: Возвратные средства без НДС (справочно) | D40: - | E40: - | F40: - | G40: =Возврат!J13 -> 31.51 | H40: =G40 -> 31.51

Sheet ОСР 02-01
A1: ОБЪЕКТНАЯ СМЕТА № ОС 02-01
A3: =ССРСС!A11 -> Выполнение работ по капитальному ремонту здания в Басманном районе ЦАО города Москвы
A4: (наименование объекта, комплекса работ и затрат)
A6: Сметная стоимость | D6: =H34 -> 51077.1 | E6: тыс.руб.
A9: Составлен(а) в уровне текущих (прогнозных) цен II квартал 2026 года
A11: № п/п | B11: Номера локальных сметных расчетов (смет) | C11: Наименование работ и затрат | D11: Сметная стоимость, тыс.руб.
D12: строительных (ремонтно-строительных) работ | E12: работ по монтажу оборудования | F12: оборудования, мебели и инвентаря | G12: прочих затрат | H12: всего
A13: 1 | B13: 2 | C13: 3 | D13: 4 | E13: 5 | F13: 6 | G13: 7 | H13: 8
A14: 1 | B14: ЛС 02-01-01 | C14: Архитектурные решения | D14: ='ЛС 02-01-01'!J14 -> 16184.58 | E14: - | F14: ='ЛС 02-01-01'!J15 -> 9.39 | G14: - | H14: =SUM(D14:G14) -> 16193.97
A15: 2 | B15: ЛС 02-01-02 | C15: Демонтажные работы | D15: ='ЛС 02-01-02'!J14 -> 137.41 | E15: ='ЛС 02-01-02'!J15 -> 40.53 | F15: - | G15: - | H15: =SUM(D15:G15) -> 177.94
A16: 3 | B16: ЛС 02-01-03 | C16: Система электроснабжения | D16: ='ЛС 02-01-03'!J14 -> 456.62 | E16: ='ЛС 02-01-03'!J15 -> 8504.41 | F16: ='ЛС 02-01-03'!J16 -> 3088.99 | G16: - | H16: =SUM(D16:G16) -> 12050.02
A17: 4 | B17: ЛС 02-01-04 | C17: Система водоснабжения | D17: ='ЛС 02-01-04'!J14 -> 568.39 | E17: ='ЛС 02-01-04'!J15 -> 14.13 | F17: - | G17: - | H17: =SUM(D17:G17) -> 582.52
A18: 5 | B18: ЛС 02-01-05 | C18: Система водоотведения | D18: ='ЛС 02-01-05'!J14 -> 841.37 | E18: - | F18: - | G18: - | H18: =SUM(D18:G18) -> 841.37
A19: 6 | B19: ЛС 02-01-06 | C19: Отопление | D19: ='ЛС 02-01-06'!J14 -> 611.12 | E19: ='ЛС 02-01-06'!J15 -> 4.57 | F19: ='ЛС 02-01-06'!J16 -> 3.42 | G19: - | H19: =SUM(D19:G19) -> 619.11
A20: 7 | B20: ЛС 02-01-07 | C20: Кондиционирование | D20: ='ЛС 02-01-07'!J14 -> 575.3 | E20: ='ЛС 02-01-07'!J15 -> 6.54 | F20: ='ЛС 02-01-07'!J16 -> 1228.01 | G20: - | H20: =SUM(D20:G20) -> 1809.85
A21: 8 | B21: ЛС 02-01-08 | C21: Автоматическая пожарная сигнализация | D21: ='ЛС 02-01-08'!J14 -> 50.39 | E21: ='ЛС 02-01-08'!J15 -> 1044.06 | F21: ='ЛС 02-01-08'!J16 -> 400.68 | G21: - | H21: =SUM(D21:G21) -> 1495.13
A22: 9 | B22: ЛС 02-01-09 | C22: Система оповещения и управления эвакуацией | D22: ='ЛС 02-01-09'!J14 -> 9.71 | E22: ='ЛС 02-01-09'!J15 -> 1243.28 | F22: ='ЛС 02-01-09'!J16 -> 220.82 | G22: - | H22: =SUM(D22:G22) -> 1473.81
A23: 10 | B23: ЛС 02-01-10 | C23: Система охранно-тревожной сигнализации. | D23: ='ЛС 02-01-10'!J14 -> 86.71 | E23: ='ЛС 02-01-10'!J15 -> 792.76 | F23: ='ЛС 02-01-10'!J16 -> 407.16 | G23: - | H23: =SUM(D23:G23) -> 1286.63
A24: 11 | B24: ЛС 02-01-11 | C24: Радиотрансляционная сеть | D24: ='ЛС 02-01-11'!J14 -> 7.09 | E24: ='ЛС 02-01-11'!J15 -> 146.82 | F24: ='ЛС 02-01-11'!J16 -> 1309.56 | G24: - | H24: =SUM(D24:G24) -> 1463.47
A25: 12 | B25: ЛС 02-01-12 | C25: Система кабельного телевидения | D25: ='ЛС 02-01-12'!J14 -> 6.12 | E25: ='ЛС 02-01-12'!J15 -> 243.07 | F25: ='ЛС 02-01-12'!J16 -> 82.53 | G25: - | H25: =SUM(D25:G25) -> 331.72
A26: 13 | B26: ЛС 02-01-13 | C26: Структурированная кабельная сеть | D26: ='ЛС 02-01-13'!J14 -> 347.43 | E26: ='ЛС 02-01-13'!J15 -> 1217.23 | F26: ='ЛС 02-01-13'!J16 -> 2352.16 | G26: - | H26: =SUM(D26:G26) -> 3916.82
A27: 14 | B27: ЛС 02-01-14 | C27: Система охранного теленаблюдения | D27: ='ЛС 02-01-14'!J14 -> 126.04 | E27: ='ЛС 02-01-14'!J15 -> 872.27 | F27: ='ЛС 02-01-14'!J16 -> 567.45 | G27: - | H27: =SUM(D27:G27) -> 1565.76
A28: 15 | B28: ЛС 02-01-15 | C28: Система контроля и управления доступом | D28: ='ЛС 02-01-15'!J14 -> 37.84 | E28: ='ЛС 02-01-15'!J15 -> 2662.88 | F28: ='ЛС 02-01-15'!J16 -> 1531.58 | G28: - | H28: =SUM(D28:G28) -> 4232.3
A29: 16 | B29: ЛС 02-01-16 | C29: Система двусторонней связи | D29: ='ЛС 02-01-16'!J14 -> 2.49 | E29: ='ЛС 02-01-16'!J15 -> 40.54 | F29: ='ЛС 02-01-16'!J16 -> 54.25 | G29: - | H29: =SUM(D29:G29) -> 97.28
A30: 17 | B30: ЛС 02-01-17 | C30: Автоматизация и диспетчеризация инженерных систем | D30: - | E30: ='ЛС 02-01-17'!J14 -> 269.15 | F30: ='ЛС 02-01-17'!J15 -> 106.86 | G30: - | H30: =SUM(D30:G30) -> 376.01
A31: 18 | B31: ЛС 02-01-18 | C31: Мероприятия по противодействию террористическим актам | D31: - | E31: - | F31: ='ЛС 02-01-18'!J14 -> 2437.21 | G31: - | H31: =SUM(D31:G31) -> 2437.21
A32: 19 | B32: ЛС 02-01-19 | C32: Мероприятия по обеспечению доступа инвалидов | D32: ='ЛС 02-01-19'!J14 -> 65.76 | E32: ='ЛС 02-01-19'!J15 -> 2.31 | F32: ='ЛС 02-01-19'!J16 -> 58.11 | G32: - | H32: =SUM(D32:G32) -> 126.18
C33: в том числе оборудование необлагаемое НДС | F33: 58.11 | H33: =SUM(D33:G33) -> 58.11
C34: ИТОГО: | D34: =SUM(D14:D33) -> 20114.37 | E34: =SUM(E14:E33) -> 17104.55 | F34: =SUM(F14:F32) -> 13858.18 | G34: - | H34: =SUM(D34:G34) -> 51077.1

Sheet ЛС 02-01-01
J2: Форма № 4б
A3: =ССРСС!A11 -> Выполнение работ по капитальному ремонту здания в Басманном районе ЦАО города Москвы
A4: (наименование стройки и/или объекта)
A6: ЛОКАЛЬНЫЙ СМЕТНЫЙ РАСЧЕТ № 02-01-01
A8: Архитектурные решения
A9: (наименование работ и затрат)
I12: В базисном уровне цен | J12: В текущем уровне цен
E13: Сметная стоимость | I13: 1011.48 | J13: 16193.97 | K13: тыс.руб.
E14: Строительные работы | I14: 1009.53 | J14: 16184.58 | K14: тыс.руб.
E15: Оборудование | I15: 1.95 | J15: 9.39 | K15: тыс.руб.
E16: Средства на оплату труда | I16: 71.22 | J16: 4063.18 | K16: тыс.руб.
E17: Затраты труда | I17: 4444.17 | K17: чел.-ч.
A19: Составлен(а) по ТСН-2001 с учетом Дополнения №: 81
A20: № и период сборника коэффициентов (индексов) пересчета: Коэффициенты к ТСН-2001 МГЭ Дополнение 81, ремонт №220 II квартал 2026 года и Коэффициенты к ТСН-2001.13-2 Дополнение 47 №65 II квартал 2026 года
A21: № п/п | B21: Шифр расценки и коды ресурсов | C21: Наименование работ и затрат | D21: Ед. изм. | E21: Кол-во единиц | F21: Цена на ед. изм., руб. | G21: Попра- вочные коэффи- циенты | H21: Коэффи- циенты зимних удорожа- ний | I21: Всего в ценах на январь 2000 года, руб. | J21: Коэффи- циенты (индек- сы) пере- счета, нормы НР и СП | K21: ВСЕГО затрат в текущем уровне цен, руб.
A22: 1 | B22: 2 | C22: 3 | D22: 4 | E22: 5 | F22: 6 | G22: 7 | H22: 8 | I22: 9 | J22: 10 | K22: 11
A23: Подраздел: Фасад
A24: 1 | B24: 3.9-66-1 | C24: Установка флагодержателей стальных | D24: 1 флагодержатель | E24: 1
C25: ЗП | F25: 6.04 | G25: 1,15*1,2 | H25: 1 | I25: 8.34 | J25: 57.05 | K25: 475.8
C26: МР | F26: 0.31 | H26: 1 | I26: 0.31 | J26: 11.39 | K26: 3.53
A27: 1,1 | B27: 1.7-8-7 | C27: Флагодержатель из листовой стали, для двух флагов, окрашенный, размер 145х300х80 мм | D27: шт. | E27: 1 | F27: 68.18 | H27: 1 | I27: 68.18 | J27: 10.43 | K27: 711.12
C28: НР от ФОТ | D28: % | E28: 84 | I28: 7.01 | J28: 84 | K28: 399.67
C29: СП от ФОТ | D29: % | E29: 53 | I29: 4.42 | J29: 53 | K29: 252.17
C30: ЗТР | D30: чел-ч | E30: 0.52 | G30: 1,15*1,2 | H30: 1 | I30: 0.72
C31: ВСЕГО работ по позиции: | H31: 88.26 | J31: 1842.29
C32: ВСЕГО по позиции: | H32: 88.26 | J32: 1842.29
A34: 2 | B34: 3.9-65-3 | C34: Установка номерных табличек с номерами подъезда и квартир / установка домового знака | D34: 1 ШТ. | E34: 1
C35: ЗП | F35: 10.9 | G35: 1,15*1,2 | H35: 1 | I35: 15.04 | J35: 57.05 | K35: 858.03
C36: МР | F36: 1 | H36: 1 | I36: 1 | J36: 16.42 | K36: 16.42
A37: 2,1 | B37: 13.3-2-63 | C37: ОБОРУДОВАНИЕ:_x000D_ Табло фасадное, габаритные размеры 300х400 мм. Материал анодированный алюминий | D37: шт. | E37: 1 | F37: 1952.68 | H37: 1 | I37: 1952.68 | J37: 4.81 | K37: 9392.39
C38: НР от ФОТ | D38: % | E38: 84 | I38: 12.63 | J38: 84 | K38: 720.75
C39: СП от ФОТ | D39: % | E39: 53 | I39: 7.97 | J39: 53 | K39: 454.76
C40: ЗТР | D40: чел-ч | E40: 0.95 | G40: 1,15*1,2 | H40: 1 | I40: 1.31
C41: ВСЕГО работ по позиции: | H41: 36.64 | J41: 2049.96
C42: ВСЕГО оборудование по позиции: | H42: 1952.68 | J42: 9392.39
C43: ВСЕГО по позиции: | H43: 1989.32 | J43: 11442.35
A46: Итого по подразделу: Фасад | H46: 2077.58 | J46: 13284.64
A48: Подраздел: Кровля
A49: 3 | B49: 6.58-18-2 | C49: Устройство настенных желобов из листовой стали | D49: 100 м | E49: 0.583
C50: Объем: 0,583=58,3/100
...

Sheet ЛС 02-01-02
J2: Форма № 4б
A3: =ССРСС!A11 -> Выполнение работ по капитальному ремонту здания в Басманном районе ЦАО города Москвы
A4: (наименование стройки и/или объекта)
A6: ЛОКАЛЬНЫЙ СМЕТНЫЙ РАСЧЕТ № 02-01-02
A8: Демонтажные работы
A9: (наименование работ и затрат)
I12: В базисном уровне цен | J12: В текущем уровне цен
E13: Сметная стоимость | I13: 3.15 | J13: 177.94 | K13: тыс.руб.
E14: Строительные работы | I14: 2.43 | J14: 137.41 | K14: тыс.руб.
E15: Работы по монтажу оборудования | I15: 0.72 | J15: 40.53 | K15: тыс.руб.
E16: Средства на оплату труда | I16: 1.32 | J16: 75.45 | K16: тыс.руб.
E17: Затраты труда | I17: 114.48 | K17: чел.-ч.
A19: Составлен(а) по ТСН-2001 с учетом Дополнения №: 81
A20: № и период сборника коэффициентов (индексов) пересчета: Коэффициенты к ТСН-2001 МГЭ Дополнение 81, ремонт №220 II квартал 2026 года и Коэффициенты к ТСН-2001.13-2 Дополнение 47 №65 II квартал 2026 года
A21: № п/п | B21: Шифр расценки и коды ресурсов | C21: Наименование работ и затрат | D21: Ед. изм. | E21: Кол-во единиц | F21: Цена на ед. изм., руб. | G21: Попра- вочные коэффи- циенты | H21: Коэффи- циенты зимних удорожа- ний | I21: Всего в ценах на январь 2000 года, руб. | J21: Коэффи- циенты (индек- сы) пере- счета, нормы НР и СП | K21: ВСЕГО затрат в текущем уровне цен, руб.
A22: 1 | B22: 2 | C22: 3 | D22: 4 | E22: 5 | F22: 6 | G22: 7 | H22: 8 | I22: 9 | J22: 10 | K22: 11
A24: Раздел: Электроснабжение
A25: 1 | B25: 4.8-251-9 | C25: Демонтаж щитка осветительного, устанавливаемого на стене распорными дюбелями, масса щитка до 6 кг / демонтаж | D25: 1 ШТ. | E25: 21
C26: ЗП | F26: 37.67 | G26: 1,2*0,3 | H26: 1 | I26: 284.79 | J26: 57.05 | K26: 16247.27
C27: ЭМ | F27: 1.32 | G27: 1,2*0,3 | H27: 1 | I27: 9.98 | J27: 14.96 | K27: 149.3
C28: в т.ч. ЗПМ | F28: 0.13 | G28: 1,2*0,3 | H28: 1 | I28: 0.98 | J28: 57.05 | K28: 55.91
C29: НР от ФОТ | D29: % | E29: 97 | I29: 277.2 | J29: 97 | K29: 15814.08
C30: СП от ФОТ | D30: % | E30: 51 | I30: 145.74 | J30: 51 | K30: 8314.62
C31: ЗТР | D31: чел-ч | E31: 2.9 | G31: 1,2*0,3 | H31: 1 | I31: 21.92
C32: ВСЕГО работ по позиции: | H32: 717.71 | J32: 40525.27
C33: ВСЕГО по позиции: | H33: 717.71 | J33: 40525.27
A35: 2 | B35: 6.67-4-1 | C35: Демонтаж электропроводки скрытой | D35: 100 м | E35: 3.92
C36: Объем: 3,92=392/100
C37: ЗП | F37: 26.44 | H37: 1 | I37: 103.64 | J37: 57.05 | K37: 5912.66
C38: НР от ФОТ | D38: % | E38: 91 | I38: 94.31 | J38: 91 | K38: 5380.52
C39: СП от ФОТ | D39: % | E39: 48 | I39: 49.75 | J39: 48 | K39: 2838.08
C40: ЗТР | D40: чел-ч | E40: 2.54 | H40: 1 | I40: 9.96
C41: ВСЕГО работ по позиции: | H41: 247.7 | J41: 14131.26
C42: ВСЕГО по позиции: | H42: 247.7 | J42: 14131.26
A45: Итого по разделу: Электроснабжение | H45: 965.41 | J45: 54656.53
A47: Раздел: Водоснабжение и водоотведение
A48: 8 | B48: 6.65-1-1 | C48: Разборка трубопроводов из водогазопроводных труб диаметром до 25 мм | D48: 100 м | E48: 0.66
C49: Объем: 0,66=(5+21+40)/100
C50: ЗП | F50: 284.19 | G50: 1,2 | H50: 1 | I50: 225.08 | J50: 57.05 | K50: 12840.81
C51: ЭМ | F51: 0.7 | G51: 1,2 | H51: 1 | I51: 0.55 | J51: 9.71 | K51: 5.34
...

Sheet ЛС 02-01-03
J2: Форма № 4б
A3: =ССРСС!A11 -> Выполнение работ по капитальному ремонту здания в Басманном районе ЦАО города Москвы
A4: (наименование стройки и/или объекта)
A6: ЛОКАЛЬНАЯ СМЕТА № 02-01-03
A8: ЭОМ
A9: (наименование работ и затрат)
I12: В базисном уровне цен | J12: В текущем уровне цен
E13: Сметная стоимость | I13: 1126.21 | J13: 12050.02 | K13: тыс.руб.
E14: Строительные работы | I14: 36.78 | J14: 456.62 | K14: тыс.руб.
E15: Работы по монтажу оборудования | I15: 679.75 | J15: 8504.41 | K15: тыс.руб.
E16: Оборудование | I16: 409.68 | J16: 3088.99 | K16: тыс.руб.
E17: Средства на оплату труда | I17: 30.72 | J17: 1752.76 | K17: тыс.руб.
E18: Затраты труда | I18: 2394.12 | K18: чел.-ч.
A20: Составлен(а) по ТСН-2001 с учетом Дополнения №: 81
A21: № и период сборника коэффициентов (индексов) пересчета: Коэффициенты к ТСН-2001 МГЭ Дополнение 81, ремонт №220 II квартал 2026 года и Коэффициенты к ТСН-2001.13-2 Дополнение 47 №65 II квартал 2026 года
A22: № п/п | B22: Шифр расценки и коды ресурсов | C22: Наименование работ и затрат | D22: Ед. изм. | E22: Кол-во единиц | F22: Цена на ед. изм., руб. | G22: Попра- вочные коэффи- циенты | H22: Коэффи- циенты зимних удорожа- ний | I22: Всего в ценах на январь 2000 года, руб. | J22: Коэффи- циенты (индек- сы) пере- счета, нормы НР и СП | K22: ВСЕГО затрат в текущем уровне цен, руб.
A23: 1 | B23: 2 | C23: 3 | D23: 4 | E23: 5 | F23: 6 | G23: 7 | H23: 8 | I23: 9 | J23: 10 | K23: 11
A24: Раздел: ВРУ
A25: 1 | B25: 4.8-238-2 Поправка: Гл.12.Прил.8.п.8. 3_12.00.01.11.001 | C25: Монтаж щитов и стеллажей с блоками резисторов (ящиками сопротивлений) высотой свыше 1700 мм, щита, собираемого из отдельных панелей и блоков управления, однорядного или двухрядного, без блоков резисторов глубиной до 800 мм шкафного исполнения | D25: 1 м ширины по фронту | E25: 0.8
C26: ЗП | F26: 267.59 | G26: 1,2 | H26: 1 | I26: 256.89 | J26: 57.05 | K26: 14655.57
C27: ЭМ | F27: 95.26 | G27: 1,2 | H27: 1 | I27: 91.45 | J27: 16.55 | K27: 1513.5
C28: в т.ч. ЗПМ | F28: 11.61 | G28: 1,2 | H28: 1 | I28: 11.15 | J28: 57.05 | K28: 636.11
C29: МР | F29: 263.81 | H29: 1 | I29: 211.05 | J29: 3.7 | K29: 780.89
A30: 1,1 | B30: 1.1-1-8146 | C30: Болты стальные оцинкованные с шестигранной головкой, с полной резьбой, с гайкой оцинкованной, М6, длина от 12 до 60 мм | D30: кг | E30: 1 | F30: 31.08 | H30: 1 | I30: 31.08 | J30: 3.59 | K30: 111.58
C31: НР от ФОТ | D31: % | E31: 97 | I31: 260 | J31: 97 | K31: 14832.93
C32: СП от ФОТ | D32: % | E32: 51 | I32: 136.7 | J32: 51 | K32: 7798.76
C33: ЗТР | D33: чел-ч | E33: 20.6 | G33: 1,2 | H33: 1 | I33: 19.78
C34: ВСЕГО работ по позиции: | H34: 987.17 | J34: 39693.23
C35: ВСЕГО по позиции: | H35: 987.17 | J35: 39693.23
A37: 2 | B37: Прайс-лист | C37: ОБОРУДОВАНИЕ:_x000D_ Вводная панель 800х450х1800 37 841,08 = [333 946,55 / 1,22 / 7,54] + 3% Трансп + 1,2% Заг.скл | D37: ШТ | E37: 1 | F37: 37841.08 | H37: 1 | I37: 37841.08 | J37: 7.54 | K37: 285321.74
C38: ВСЕГО по позиции: | H38: 37841.08 | J38: 285321.74
A40: 3 | B40: 4.8-238-2 Поправка: Гл.12.Прил.8.п.8. 3_12.00.01.11.001 | C40: Монтаж щитов и стеллажей с блоками резисторов (ящиками сопротивлений) высотой свыше 1700 мм, щита, собираемого из отдельных панелей и блоков управления, однорядного или двухрядного, без блоков резисторов глубиной до 800 мм шкафного исполнения | D40: 1 м ширины по фронту | E40: 0.45
C41: ЗП | F41: 267.59 | G41: 1,2 | H41: 1 | I41: 144.5 | J41: 57.05 | K41: 8243.73
C42: ЭМ | F42: 95.26 | G42: 1,2 | H42: 1 | I42: 51.44 | J42: 16.55 | K42: 851.33
C43: в т.ч. ЗПМ | F43: 11.61 | G43: 1,2 | H43: 1 | I43: 6.27 | J43: 57.05 | K43: 357.7
C44: МР | F44: 263.81 | H44: 1 | I44: 118.71 | J44: 3.7 | K44: 439.23
A45: 3,1 | B45: 1.1-1-8146 Поправка: Гл.12.Прил.8.п.8. 3_12.00.01.11.001 | C45: Болты стальные оцинкованные с шестигранной головкой, с полной резьбой, с гайкой оцинкованной, М6, длина от 12 до 60 мм | D45: кг | E45: 0.5625 | F45: 31.08 | H45: 1 | I45: 17.48 | J45: 3.59 | K45: 62.75
C46: НР от ФОТ | D46: % | E46: 97 | I46: 146.25 | J46: 97 | K46: 8343.39
C47: СП от ФОТ | D47: % | E47: 51 | I47: 76.89 | J47: 51 | K47: 4386.73
C48: ЗТР | D48: чел-ч | E48: 20.6 | G48: 1,2 | H48: 1 | I48: 11.12
...

Sheet ЛС 02-01-04
J2: Форма № 4б
A3: =ССРСС!A11 -> Выполнение работ по капитальному ремонту здания в Басманном районе ЦАО города Москвы
A4: (наименование стройки и/или объекта)
A6: ЛОКАЛЬНАЯ СМЕТА № 02-01-04
A8: Водоснабжение
A9: (наименование работ и затрат)
I12: В базисном уровне цен | J12: В текущем уровне цен
E13: Сметная стоимость | I13: 38.23 | J13: 582.52 | K13: тыс.руб.
E14: Строительные работы | I14: 37.97 | J14: 568.39 | K14: тыс.руб.
E15: Работы по монтажу оборудования | I15: 0.26 | J15: 14.13 | K15: тыс.руб.
E16: Средства на оплату труда | I16: 2.28 | J16: 129.93 | K16: тыс.руб.
E17: Затраты труда | I17: 180.6 | K17: чел.-ч.
A19: Составлен(а) по ТСН-2001 с учетом Дополнения №: 81
A20: № и период сборника коэффициентов (индексов) пересчета: Коэффициенты к ТСН-2001 МГЭ Дополнение 81, ремонт №220 II квартал 2026 года и Коэффициенты к ТСН-2001.13-2 Дополнение 47 №65 II квартал 2026 года
A21: № п/п | B21: Шифр расценки и коды ресурсов | C21: Наименование работ и затрат | D21: Ед. изм. | E21: Кол-во единиц | F21: Цена на ед. изм., руб. | G21: Попра- вочные коэффи- циенты | H21: Коэффи- циенты зимних удорожа- ний | I21: Всего в ценах на январь 2000 года, руб. | J21: Коэффи- циенты (индек- сы) пере- счета, нормы НР и СП | K21: ВСЕГО затрат в текущем уровне цен, руб.
A22: 1 | B22: 2 | C22: 3 | D22: 4 | E22: 5 | F22: 6 | G22: 7 | H22: 8 | I22: 9 | J22: 10 | K22: 11
A23: Раздел: Внутренние сети холодного водоснабжения
A24: 1 | B24: 3.16-38-1 Поправка: Гл.6.Прил.2.2.п.2.2.6_06.00.01.07.001 Поправка: Гл.12.Прил.8.п.8. 3_12.00.01.11.001 | C24: Прокладка трубопроводов из стальных труб на бессварных разъемных муфтовых соединениях диаметром до 25 мм | D24: 100 м | E24: 0.66
C25: Объем: 0,66=(5+21+40)/100
C26: ЗП | F26: 236.83 | G26: 1,15*1,2 | H26: 1 | I26: 215.7 | J26: 57.05 | K26: 12305.69
C27: ЭМ | F27: 4.07 | G27: 1,25*1,2 | H27: 1 | I27: 4.03 | J27: 13.79 | K27: 55.57
C28: в т.ч. ЗПМ | F28: 0.3 | G28: 1,25*1,2 | H28: 1 | I28: 0.3 | J28: 57.05 | K28: 17.12
C29: МР | F29: 30.04 | H29: 1 | I29: 19.83 | J29: 1.83 | K29: 36.29
C30: НР от ФОТ | D30: % | E30: 109 | I30: 235.44 | J30: 109 | K30: 13431.86
C31: СП от ФОТ | D31: % | E31: 61 | I31: 131.76 | J31: 61 | K31: 7516.91
C32: ЗТР | D32: чел-ч | E32: 19.12 | G32: 1,15*1,2 | H32: 1 | I32: 17.41
C33: ВСЕГО работ по позиции: | H33: 606.76 | J33: 33346.32
C34: ВСЕГО по позиции: | H34: 606.76 | J34: 33346.32
A36: 2 | B36: 1.12-1-52 | C36: Узел трубопровода из стальных водогазопроводных оцинкованных труб, с гильзами, для водоснабжения, диаметр условного прохода 15 мм | D36: м | E36: 5 | F36: 28.1 | H36: 1 | I36: 140.5 | J36: 18.63 | K36: 2617.52
C37: ВСЕГО по позиции: | H37: 140.5 | J37: 2617.52
A39: 3 | B39: 1.12-2-1163 | C39: Хомуты из оцинкованной стали с резиновыми прокладками для жесткого и скользящего крепления полипропиленовых труб, наружный диаметр 20 мм/15мм | D39: шт. | E39: 130 | F39: 17.33 | H39: 1 | I39: 2252.9 | J39: 0.98 | K39: 2207.84
C40: ВСЕГО по позиции: | H40: 2252.9 | J40: 2207.84
A42: 4 | B42: 1.12-1-53 | C42: Узел трубопровода из стальных водогазопроводных оцинкованных труб, с гильзами, для водоснабжения, диаметр условного прохода 20 мм | D42: м | E42: 21 | F42: 31.41 | H42: 1 | I42: 659.61 | J42: 18.51 | K42: 12209.38
C43: ВСЕГО по позиции: | H43: 659.61 | J43: 12209.38
A45: 5 | B45: 1.12-2-1163 | C45: Хомуты из оцинкованной стали с резиновыми прокладками для жесткого и скользящего крепления полипропиленовых труб, наружный диаметр 20 мм | D45: шт. | E45: 20 | F45: 17.33 | H45: 1 | I45: 346.6 | J45: 0.98 | K45: 339.67
C46: ВСЕГО по позиции: | H46: 346.6 | J46: 339.67
A48: 6 | B48: 1.1-1-59 | C48: Болты строительные анкерные с гайками | D48: т | E48: 0.00072 | F48: 26867.38 | H48: 1 | I48: 19.34 | J48: 4.39 | K48: 84.9
C49: Объем: 0,00072=0,018*40/1000
C50: ВСЕГО по позиции: | H50: 19.34 | J50: 84.9
A52: 7 | B52: 1.12-1-54 | C52: Узел трубопровода из стальных водогазопроводных оцинкованных труб, с гильзами, для водоснабжения, диаметр условного прохода 25 мм | D52: м | E52: 40 | F52: 41.57 | H52: 1 | I52: 1662.8 | J52: 16.56 | K52: 27535.97
...

Sheet ЛС 02-01-05
J2: Форма № 4б
A3: =ССРСС!A11 -> Выполнение работ по капитальному ремонту здания в Басманном районе ЦАО города Москвы
A4: (наименование стройки и/или объекта)
A6: ЛОКАЛЬНАЯ СМЕТА № 02-01-05
A8: Водоотведение
A9: (наименование работ и затрат)
I12: В базисном уровне цен | J12: В текущем уровне цен
E13: Сметная стоимость | I13: 66.73 | J13: 841.37 | K13: тыс.руб.
E14: Строительные работы | I14: 66.73 | J14: 841.37 | K14: тыс.руб.
E15: Средства на оплату труда | I15: 2.3 | J15: 131.45 | K15: тыс.руб.
E16: Затраты труда | I16: 185.35 | K16: чел.-ч.
A18: Составлен(а) по ТСН-2001 с учетом Дополнения №: 81
A19: № и период сборника коэффициентов (индексов) пересчета: Коэффициенты к ТСН-2001 МГЭ Дополнение 81, ремонт №220 II квартал 2026 года и Коэффициенты к ТСН-2001.13-2 Дополнение 47 №65 II квартал 2026 года
A20: № п/п | B20: Шифр расценки и коды ресурсов | C20: Наименование работ и затрат | D20: Ед. изм. | E20: Кол-во единиц | F20: Цена на ед. изм., руб. | G20: Попра- вочные коэффи- циенты | H20: Коэффи- циенты зимних удорожа- ний | I20: Всего в ценах на январь 2000 года, руб. | J20: Коэффи- циенты (индек- сы) пере- счета, нормы НР и СП | K20: ВСЕГО затрат в текущем уровне цен, руб.
A21: 1 | B21: 2 | C21: 3 | D21: 4 | E21: 5 | F21: 6 | G21: 7 | H21: 8 | I21: 9 | J21: 10 | K21: 11
A22: Раздел: Канализация хозяйственно-бытовая (К1)
A23: 1 | B23: 3.16-2-3 Поправка: Гл.6.Прил.2.2.п.2.2.6_06.00.01.07.001 Поправка: Гл.12.Прил.8.п.8. 3_12.00.01.11.001 | C23: Прокладка по стенам зданий и в каналах труб чугунных напорных раструбных диаметром 100 мм | D23: 100 м труб | E23: 0.5
C24: Объем: 0,5=50/100
C25: ЗП | F25: 1395.48 | G25: 1,15*1,2 | H25: 1 | I25: 962.88 | J25: 57.05 | K25: 54932.3
C26: ЭМ | F26: 144.95 | G26: 1,25*1,2 | H26: 1 | I26: 108.71 | J26: 17.13 | K26: 1862.2
C27: в т.ч. ЗПМ | F27: 20.7 | G27: 1,25*1,2 | H27: 1 | I27: 15.53 | J27: 57.05 | K27: 885.99
C28: МР | F28: 202.76 | H28: 1 | I28: 101.38 | J28: 10.9 | K28: 1105.04
A29: 1,1 | B29: 1.12-1-69 | C29: Узлы трубопроводов из чугунных канализационных труб с фасонными частями, диаметр условного прохода 100 мм | D29: м | E29: 50.5 | F29: 129.06 | H29: 1 | I29: 6517.53 | J29: 24.94 | K29: 162547.2
C30: НР от ФОТ | D30: % | E30: 109 | I30: 1066.47 | J30: 109 | K30: 60841.94
C31: СП от ФОТ | D31: % | E31: 61 | I31: 596.83 | J31: 61 | K31: 34049.16
C32: ЗТР | D32: чел-ч | E32: 116 | G32: 1,15*1,2 | H32: 1 | I32: 80.04
C33: ВСЕГО работ по позиции: | H33: 9353.8 | J33: 315337.84
C34: ВСЕГО по позиции: | H34: 9353.8 | J34: 315337.84
A36: 2 | B36: 1.12-10-16 | C36: Ревизия чугунная, диаметр условного прохода 100 мм | D36: шт. | E36: 6 | F36: 66.36 | H36: 1 | I36: 398.16 | J36: 23.78 | K36: 9468.24
C37: ВСЕГО по позиции: | H37: 398.16 | J37: 9468.24
A39: 3 | B39: 3.16-28-2 Поправка: Гл.6.Прил.2.2.п.2.2.6_06.00.01.07.001 Поправка: Гл.12.Прил.8.п.8. 3_12.00.01.11.001 | C39: Врезки в действующие внутренние сети трубопроводов канализации диаметром 100 мм | D39: 1 врезка | E39: 1
C40: ЗП | F40: 99.95 | G40: 1,15*1,2 | H40: 1 | I40: 137.93 | J40: 57.05 | K40: 7868.91
C41: ЭМ | F41: 0.83 | G41: 1,25*1,2 | H41: 1 | I41: 1.25 | J41: 17.47 | K41: 21.84
C42: в т.ч. ЗПМ | F42: 0.13 | G42: 1,25*1,2 | H42: 1 | I42: 0.2 | J42: 57.05 | K42: 11.41
C43: МР | F43: 8.01 | H43: 1 | I43: 8.01 | J43: 22.99 | K43: 184.15
C44: НР от ФОТ | D44: % | E44: 109 | I44: 150.56 | J44: 109 | K44: 8589.55
C45: СП от ФОТ | D45: % | E45: 61 | I45: 84.26 | J45: 61 | K45: 4807
C46: ЗТР | D46: чел-ч | E46: 8.94 | G46: 1,15*1,2 | H46: 1 | I46: 12.34
C47: ВСЕГО работ по позиции: | H47: 382.01 | J47: 21471.45
C48: ВСЕГО по позиции: | H48: 382.01 | J48: 21471.45
...

Sheet ЛС 02-01-06
J2: Форма № 4б
A3: =ССРСС!A11 -> Выполнение работ по капитальному ремонту здания в Басманном районе ЦАО города Москвы
A4: (наименование стройки и/или объекта)
A6: ЛОКАЛЬНАЯ СМЕТА № 02-01-06
A8: Отопление
A9: (наименование работ и затрат)
I12: В базисном уровне цен | J12: В текущем уровне цен
E13: Сметная стоимость | I13: 68.45 | J13: 619.11 | K13: тыс.руб.
E14: Строительные работы | I14: 67.91 | J14: 611.12 | K14: тыс.руб.
E15: Работы по монтажу оборудования | I15: 0.08 | J15: 4.57 | K15: тыс.руб.
E16: Оборудование | I16: 0.46 | J16: 3.42 | K16: тыс.руб.
E17: Средства на оплату труда | I17: 1.59 | J17: 90.69 | K17: тыс.руб.
E18: Затраты труда | I18: 123.28 | K18: чел.-ч.
A20: Составлен(а) по ТСН-2001 с учетом Дополнения №: 81
A21: № и период сборника коэффициентов (индексов) пересчета: Коэффициенты к ТСН-2001 МГЭ Дополнение 81, ремонт №220 II квартал 2026 года и Коэффициенты к ТСН-2001.13-2 Дополнение 47 №65 II квартал 2026 года
A22: № п/п | B22: Шифр расценки и коды ресурсов | C22: Наименование работ и затрат | D22: Ед. изм. | E22: Кол-во единиц | F22: Цена на ед. изм., руб. | G22: Попра- вочные коэффи- циенты | H22: Коэффи- циенты зимних удорожа- ний | I22: Всего в ценах на январь 2000 года, руб. | J22: Коэффи- циенты (индек- сы) пере- счета, нормы НР и СП | K22: ВСЕГО затрат в текущем уровне цен, руб.
A23: 1 | B23: 2 | C23: 3 | D23: 4 | E23: 5 | F23: 6 | G23: 7 | H23: 8 | I23: 9 | J23: 10 | K23: 11
A24: Раздел: Устакновка радиаторов
A25: 1 | B25: 3.18-26-1 Поправка: Гл.6.Прил.2.2.п.2.2.6_06.00.01.07.001 Поправка: Гл.12.Прил.8.п.8. 3_12.00.01.11.001 Поправка: 3-18. О.П. п.1.8 | C25: Установка радиаторов алюминиевых и биметаллических с креплением к стене с числом секций до 4 шт. | D25: 100 шт. | E25: 0.02
C26: Объем: 0,02=2/100
C27: ЗП | F27: 716.97 | G27: 1,15*1,2*1,03 | H27: 1 | I27: 20.38 | J27: 57.05 | K27: 1162.68
C28: ЭМ | F28: 28.37 | G28: 1,25*1,2*1,03 | H28: 1 | I28: 0.88 | J28: 15.89 | K28: 13.98
C29: в т.ч. ЗПМ | F29: 3.21 | G29: 1,25*1,2*1,03 | H29: 1 | I29: 0.1 | J29: 57.05 | K29: 5.71
C30: МР | F30: 2962.2 | H30: 1 | I30: 59.24 | J30: 7.01 | K30: 415.27
C31: НР от ФОТ | D31: % | E31: 109 | I31: 22.32 | J31: 109 | K31: 1273.55
C32: СП от ФОТ | D32: % | E32: 61 | I32: 12.49 | J32: 61 | K32: 712.72
C33: ЗТР | D33: чел-ч | E33: 58.34 | G33: 1,15*1,2*1,03 | H33: 1 | I33: 1.66
C34: ВСЕГО работ по позиции: | H34: 115.31 | J34: 3578.2
C35: ВСЕГО по позиции: | H35: 115.31 | J35: 3578.2
A37: 2 | B37: 1.18-4-1270 | C37: Радиатор отопительный, биметаллический, секционный, ГОСТ 31311, размер секции 80х95х360 мм, межосевое расстояние 300 мм, 4 секции, теплоотдача 0,484 кВт | D37: шт. | E37: 2 | F37: 676.08 | H37: 1 | I37: 1352.16 | J37: 4.79 | K37: 6476.85
C38: ВСЕГО по позиции: | H38: 1352.16 | J38: 6476.85
A40: 3 | B40: 3.18-26-2 Поправка: Гл.6.Прил.2.2.п.2.2.6_06.00.01.07.001 Поправка: Гл.12.Прил.8.п.8. 3_12.00.01.11.001 Поправка: 3-18. О.П. п.1.8 | C40: Установка радиаторов алюминиевых и биметаллических с креплением к стене с числом секций свыше 4 до 10 шт. | D40: 100 шт. | E40: 0.23
C41: Объем: 0,23=(3+3+9+3+4+1)/100
C42: ЗП | F42: 873.14 | G42: 1,15*1,2*1,03 | H42: 1 | I42: 285.45 | J42: 57.05 | K42: 16284.92
C43: ЭМ | F43: 80.36 | G43: 1,25*1,2*1,03 | H43: 1 | I43: 28.56 | J43: 15.84 | K43: 452.39
C44: в т.ч. ЗПМ | F44: 8.91 | G44: 1,25*1,2*1,03 | H44: 1 | I44: 3.17 | J44: 57.05 | K44: 180.85
C45: МР | F45: 3737.88 | H45: 1 | I45: 859.71 | J45: 6.64 | K45: 5708.47
C46: НР от ФОТ | D46: % | E46: 109 | I46: 314.6 | J46: 109 | K46: 17947.69
C47: СП от ФОТ | D47: % | E47: 61 | I47: 176.06 | J47: 61 | K47: 10044.12
C48: ЗТР | D48: чел-ч | E48: 71.13 | G48: 1,15*1,2*1,03 | H48: 1 | I48: 23.25
...

Sheet ЛС 02-01-07
J2: Форма № 4б
A3: =ССРСС!A11 -> Выполнение работ по капитальному ремонту здания в Басманном районе ЦАО города Москвы
A4: (наименование стройки и/или объекта)
A6: ЛОКАЛЬНАЯ СМЕТА № 02-01-07
A8: Кондиционирование
A9: (наименование работ и затрат)
I12: В базисном уровне цен | J12: В текущем уровне цен
E13: Сметная стоимость | I13: 187.84 | J13: 1809.85 | K13: тыс.руб.
E14: Строительные работы | I14: 24.86 | J14: 575.3 | K14: тыс.руб.
E15: Работы по монтажу оборудования | I15: 0.11 | J15: 6.54 | K15: тыс.руб.
E16: Оборудование | I16: 162.87 | J16: 1228.01 | K16: тыс.руб.
E17: Средства на оплату труда | I17: 3.16 | J17: 180.19 | K17: тыс.руб.
E18: Затраты труда | I18: 242.54 | K18: чел.-ч.
A20: Составлен(а) по ТСН-2001 с учетом Дополнения №: 81
A21: № и период сборника коэффициентов (индексов) пересчета: Коэффициенты к ТСН-2001 МГЭ Дополнение 81, ремонт №220 II квартал 2026 года и Коэффициенты к ТСН-2001.13-2 Дополнение 47 №65 II квартал 2026 года
A22: № п/п | B22: Шифр расценки и коды ресурсов | C22: Наименование работ и затрат | D22: Ед. изм. | E22: Кол-во единиц | F22: Цена на ед. изм., руб. | G22: Попра- вочные коэффи- циенты | H22: Коэффи- циенты зимних удорожа- ний | I22: Всего в ценах на январь 2000 года, руб. | J22: Коэффи- циенты (индек- сы) пере- счета, нормы НР и СП | K22: ВСЕГО затрат в текущем уровне цен, руб.
A23: 1 | B23: 2 | C23: 3 | D23: 4 | E23: 5 | F23: 6 | G23: 7 | H23: 8 | I23: 9 | J23: 10 | K23: 11
A24: Раздел: Кондиционирование
A25: 1 | B25: 3.20-59-1 Поправка: Гл.12.Прил.8.п.8. 3_12.00.01.11.001 Поправка: Гл.6.Прил.2.2.п.2.2.6_06.00.01.07.001 | C25: Установка наружного блока сплит-системы мощностью до 6,5 кВт на кронштейны | D25: 1 блок | E25: 25
C26: Объем: 25=2+2+2+1+1+1+1+1+1+1+1+1+1+1+1+1+1+1+1+1+1+1
C27: ЗП | F27: 11.06 | G27: 1,2*1,15 | H27: 1 | I27: 381.57 | J27: 57.05 | K27: 21768.57
C28: ЭМ | F28: 0.65 | G28: 1,2*1,25 | H28: 1 | I28: 24.38 | J28: 14.32 | K28: 349.12
C29: в т.ч. ЗПМ | F29: 0.06 | G29: 1,2*1,25 | H29: 1 | I29: 2.25 | J29: 57.05 | K29: 128.36
C30: МР | F30: 98.58 | H30: 1 | I30: 2464.5 | J30: 5.14 | K30: 12667.53
C31: НР от ФОТ | D31: % | E31: 109 | I31: 418.36 | J31: 109 | K31: 23867.65
C32: СП от ФОТ | D32: % | E32: 61 | I32: 234.13 | J32: 61 | K32: 13357.13
C33: ЗТР | D33: чел-ч | E33: 0.82 | G33: 1,2*1,15 | H33: 1 | I33: 28.29
C34: ВСЕГО работ по позиции: | H34: 3522.94 | J34: 72010
C35: ВСЕГО по позиции: | H35: 3522.94 | J35: 72010
A37: 2 | B37: 3.20-58-1 Поправка: Гл.12.Прил.8.п.8. 3_12.00.01.11.001 Поправка: Гл.6.Прил.2.2.п.2.2.6_06.00.01.07.001 | C37: Установка внутреннего блока сплит-системы настенного типа мощностью до 6,5 кВт | D37: 1 блок | E37: 25
C38: ЗП | F38: 79.45 | G38: 1,2*1,15 | H38: 1 | I38: 2741.03 | J38: 57.05 | K38: 156375.76
C39: ЭМ | F39: 0.89 | G39: 1,2*1,25 | H39: 1 | I39: 33.38 | J39: 12.98 | K39: 433.27
C40: в т.ч. ЗПМ | F40: 0.05 | G40: 1,2*1,25 | H40: 1 | I40: 1.88 | J40: 57.05 | K40: 107.25
C41: МР | F41: 289.06 | H41: 1 | I41: 7226.5 | J41: 8.03 | K41: 58028.8
C42: НР от ФОТ | D42: % | E42: 109 | I42: 2989.77 | J42: 109 | K42: 170566.48
C43: СП от ФОТ | D43: % | E43: 61 | I43: 1673.18 | J43: 61 | K43: 95454.64
C44: ЗТР | D44: чел-ч | E44: 6.14 | G44: 1,2*1,15 | H44: 1 | I44: 211.83
C45: ВСЕГО работ по позиции: | H45: 14663.86 | J45: 480858.95
C46: ВСЕГО по позиции: | H46: 14663.86 | J46: 480858.95
A48: 3 | B48: 1.12-5-61 Поправка: Гл.12.Прил.8.п.8. 3_12.00.01.11.001 Поправка: Гл.6.Прил.2.2.п.2.2.6_06.00.01.07.001 | C48: Трубка дренажная из ПВХ, диаметр 16 мм | D48: м | E48: -76.875 | F48: 10.78 | H48: 1 | I48: -828.71 | J48: 1.56 | K48: -1292.79
...

Sheet ЛС 02-01-08
J2: Форма № 4б
A3: =ССРСС!A11 -> Выполнение работ по капитальному ремонту здания в Басманном районе ЦАО города Москвы
A4: (наименование стройки и/или объекта)
A6: ЛОКАЛЬНАЯ СМЕТА № 02-01-08
A8: Автоматическая пожарная сигнализация
A9: (наименование работ и затрат)
I12: В базисном уровне цен | J12: В текущем уровне цен
E13: Сметная стоимость | I13: 83.58 | J13: 1495.13 | K13: тыс.руб.
E14: Строительные работы | I14: 4.95 | J14: 50.39 | K14: тыс.руб.
E15: Работы по монтажу оборудования | I15: 25.23 | J15: 1044.06 | K15: тыс.руб.
E16: Оборудование | I16: 53.4 | J16: 400.68 | K16: тыс.руб.
E17: Средства на оплату труда | I17: 7.49 | J17: 427.18 | K17: тыс.руб.
E18: Затраты труда | I18: 603.27 | K18: чел.-ч.
A20: Составлен(а) по ТСН-2001 с учетом Дополнения №: 81
A21: № и период сборника коэффициентов (индексов) пересчета: Коэффициенты к ТСН-2001 МГЭ Дополнение 81, ремонт №220 II квартал 2026 года и Коэффициенты к ТСН-2001.13-2 Дополнение 47 №65 II квартал 2026 года
A22: № п/п | B22: Шифр расценки и коды ресурсов | C22: Наименование работ и затрат | D22: Ед. изм. | E22: Кол-во единиц | F22: Цена на ед. изм., руб. | G22: Попра- вочные коэффи- циенты | H22: Коэффи- циенты зимних удорожа- ний | I22: Всего в ценах на январь 2000 года, руб. | J22: Коэффи- циенты (индек- сы) пере- счета, нормы НР и СП | K22: ВСЕГО затрат в текущем уровне цен, руб.
A23: 1 | B23: 2 | C23: 3 | D23: 4 | E23: 5 | F23: 6 | G23: 7 | H23: 8 | I23: 9 | J23: 10 | K23: 11
A24: Раздел: Монтаж оборудования
A25: 1 | B25: 4.10-80-1 Поправка: Гл.12.Прил.8.п.8. 3_12.00.01.11.001 | C25: Аппараты приемные, приборы ПС приемно-контрольные, пусковые, концентратор, блок базовый на 10 лучей | D25: 1 ШТ. | E25: 2
C26: ЗП | F26: 95.04 | G26: 1,2 | H26: 1 | I26: 228.1 | J26: 57.05 | K26: 13013.11
C27: ЭМ | F27: 0.06 | G27: 1,2 | H27: 1 | I27: 0.14 | J27: 18.83 | K27: 2.64
C28: в т.ч. ЗПМ | F28: 0.01 | G28: 1,2 | H28: 1 | I28: 0.02 | J28: 57.05 | K28: 1.14
C29: МР | F29: 12.53 | H29: 1 | I29: 25.06 | J29: 10.18 | K29: 255.11
C30: НР от ФОТ | D30: % | E30: 90 | I30: 205.31 | J30: 90 | K30: 11712.83
C31: СП от ФОТ | D31: % | E31: 46 | I31: 104.94 | J31: 46 | K31: 5986.56
C32: ЗТР | D32: чел-ч | E32: 7.2 | G32: 1,2 | H32: 1 | I32: 17.28
C33: ВСЕГО работ по позиции: | H33: 563.55 | J33: 30970.25
C34: ВСЕГО по позиции: | H34: 563.55 | J34: 30970.25
A36: 2 | B36: Прайс-лист | C36: ОБОРУДОВАНИЕ: Прибор приемно-контрольный и управления охранно-пожарный адресный 4 870,40 = [42 981,21 / 1,22 / 7,54] + 3% Трансп + 1,2% Заг.скл | D36: ШТ | E36: 2 | F36: 4870.4 | H36: 1 | I36: 9740.8 | J36: 7.54 | K36: 73445.63
C37: ВСЕГО по позиции: | H37: 9740.8 | J37: 73445.63
A39: 3 | B39: 4.10-170-2 Поправка: Гл.12.Прил.8.п.8. 3_12.00.01.11.001 | C39: Монтаж блока информационно-управляющего (БИУ) в диспетчерской | D39: 1 ШТ. | E39: 1
C40: ЗП | F40: 33.47 | G40: 1,2 | H40: 1 | I40: 40.16 | J40: 57.05 | K40: 2291.13
C41: МР | F41: 2.34 | H41: 1 | I41: 2.34 | J41: 9.91 | K41: 23.19
C42: НР от ФОТ | D42: % | E42: 90 | I42: 36.14 | J42: 90 | K42: 2062.02
C43: СП от ФОТ | D43: % | E43: 46 | I43: 18.47 | J43: 46 | K43: 1053.92
C44: ЗТР | D44: чел-ч | E44: 2.65 | G44: 1,2 | H44: 1 | I44: 3.18
C45: ВСЕГО работ по позиции: | H45: 97.11 | J45: 5430.26
C46: ВСЕГО по позиции: | H46: 97.11 | J46: 5430.26
A48: 4 | B48: Прайс-лист | C48: ОБОРУДОВАНИЕ: Блок индикации и управления 2 394,57 = [21 132 / 1,22 / 7,54] + 3% Трансп + 1,2% Заг.скл | D48: ШТ | E48: 1 | F48: 2394.57 | H48: 1 | I48: 2394.57 | J48: 7.54 | K48: 18055.06
C49: ВСЕГО по позиции: | H49: 2394.57 | J49: 18055.06
...

Sheet ЛС 02-01-09
J2: Форма № 4б
A3: =ССРСС!A11 -> Выполнение работ по капитальному ремонту здания в Басманном районе ЦАО города Москвы
A4: (наименование стройки и/или объекта)
A6: ЛОКАЛЬНАЯ СМЕТА № 02-01-09
A8: Система оповещения и управления эвакуацией
A9: (наименование работ и затрат)
I12: В базисном уровне цен | J12: В текущем уровне цен
E13: Сметная стоимость | I13: 275.46 | J13: 1473.81 | K13: тыс.руб.
E14: Строительные работы | I14: 1.03 | J14: 9.71 | K14: тыс.руб.
E15: Работы по монтажу оборудования | I15: 244.95 | J15: 1243.28 | K15: тыс.руб.
E16: Оборудование | I16: 29.48 | J16: 220.82 | K16: тыс.руб.
E17: Средства на оплату труда | I17: 1.9 | J17: 108.15 | K17: тыс.руб.
E18: Затраты труда | I18: 159.63 | K18: чел.-ч.
A20: Составлен(а) по ТСН-2001 с учетом Дополнения №: 81
A21: № и период сборника коэффициентов (индексов) пересчета: Коэффициенты к ТСН-2001 МГЭ Дополнение 81, ремонт №220 II квартал 2026 года и Коэффициенты к ТСН-2001.13-2 Дополнение 47 №65 II квартал 2026 года
A22: № п/п | B22: Шифр расценки и коды ресурсов | C22: Наименование работ и затрат | D22: Ед. изм. | E22: Кол-во единиц | F22: Цена на ед. изм., руб. | G22: Попра- вочные коэффи- циенты | H22: Коэффи- циенты зимних удорожа- ний | I22: Всего в ценах на январь 2000 года, руб. | J22: Коэффи- циенты (индек- сы) пере- счета, нормы НР и СП | K22: ВСЕГО затрат в текущем уровне цен, руб.
A23: 1 | B23: 2 | C23: 3 | D23: 4 | E23: 5 | F23: 6 | G23: 7 | H23: 8 | I23: 9 | J23: 10 | K23: 11
A24: Раздел: Монтаж оборудования
A25: 1 | B25: 4.10-75-9 Поправка: Гл.12.Прил.8.п.8. 3_12.00.01.11.001 | C25: Монтаж аппаратуры настенной | D25: 1 ШТ. | E25: 1
C26: ЗП | F26: 89.44 | G26: 1,2 | H26: 1 | I26: 107.33 | J26: 57.05 | K26: 6123.18
C27: МР | F27: 24.1 | H27: 1 | I27: 24.1 | J27: 7.35 | K27: 177.14
C28: НР от ФОТ | D28: % | E28: 95 | I28: 101.96 | J28: 95 | K28: 5817.02
C29: СП от ФОТ | D29: % | E29: 53 | I29: 56.88 | J29: 53 | K29: 3245.29
C30: ЗТР | D30: чел-ч | E30: 8 | G30: 1,2 | H30: 1 | I30: 9.6
C31: ВСЕГО работ по позиции: | H31: 290.27 | J31: 15362.63
C32: ВСЕГО по позиции: | H32: 290.27 | J32: 15362.63
A34: 2 | B34: Прайс-лист | C34: ОБОРУДОВАНИЕ: Прибор управления оповещением 13 635,74 = [120 335 / 1,22 / 7,54] + 3% Трансп + 1,2% Заг.скл | D34: ШТ | E34: 1 | F34: 13635.74 | H34: 1 | I34: 13635.74 | J34: 7.54 | K34: 102813.48
C35: ВСЕГО по позиции: | H35: 13635.74 | J35: 102813.48
A37: 3 | B37: 4.11-7-1 Поправка: Гл.12.Прил.8.п.8. 3_12.00.01.11.001 | C37: Установка аппарата настольного массой до 0,015 т | D37: 1 ШТ. | E37: 1
C38: ЗП | F38: 11.52 | G38: 1,2 | H38: 1 | I38: 13.82 | J38: 57.05 | K38: 788.43
C39: ЭМ | F39: 13.3 | G39: 1,2 | H39: 1 | I39: 15.96 | J39: 17.45 | K39: 278.5
C40: в т.ч. ЗПМ | F40: 2.02 | G40: 1,2 | H40: 1 | I40: 2.42 | J40: 57.05 | K40: 138.06
C41: НР от ФОТ | D41: % | E41: 90 | I41: 14.62 | J41: 90 | K41: 833.84
C42: СП от ФОТ | D42: % | E42: 46 | I42: 7.47 | J42: 46 | K42: 426.19
C43: ЗТР | D43: чел-ч | E43: 1.03 | G43: 1,2 | H43: 1 | I43: 1.24
C44: ВСЕГО работ по позиции: | H44: 51.87 | J44: 2326.96
C45: ВСЕГО по позиции: | H45: 51.87 | J45: 2326.96
A47: 4 | B47: Прайс-лист | C47: ОБОРУДОВАНИЕ: Пульт микрофонный 1 781,64 = [15 722,82 / 1,22 / 7,54] + 3% Трансп + 1,2% Заг.скл | D47: ШТ | E47: 1 | F47: 1781.64 | H47: 1 | I47: 1781.64 | J47: 7.54 | K47: 13433.57
C48: ВСЕГО по позиции: | H48: 1781.64 | J48: 13433.57
A50: 5 | B50: 4.10-76-7 Поправка: Гл.12.Прил.8.п.8. 3_12.00.01.11.001 | C50: Монтаж громкоговорителя или звуковой колонки в помещении | D50: 1 ШТ. | E50: 35
...

Sheet ЛС 02-01-10
J2: Форма № 4б
A3: =ССРСС!A11 -> Выполнение работ по капитальному ремонту здания в Басманном районе ЦАО города Москвы
A4: (наименование стройки и/или объекта)
A6: ЛОКАЛЬНАЯ СМЕТА № 02-01-10
A8: Система охранно-тревожной сигнализации
A9: (наименование работ и затрат)
I12: В базисном уровне цен | J12: В текущем уровне цен
E13: Сметная стоимость | I13: 84.65 | J13: 1286.63 | K13: тыс.руб.
E14: Строительные работы | I14: 8.52 | J14: 86.71 | K14: тыс.руб.
E15: Работы по монтажу оборудования | I15: 22.12 | J15: 792.76 | K15: тыс.руб.
E16: Оборудование | I16: 54.01 | J16: 407.16 | K16: тыс.руб.
E17: Средства на оплату труда | I17: 5.34 | J17: 304.39 | K17: тыс.руб.
E18: Затраты труда | I18: 419.05 | K18: чел.-ч.
A20: Составлен(а) по ТСН-2001 с учетом Дополнения №: 81
A21: № и период сборника коэффициентов (индексов) пересчета: Коэффициенты к ТСН-2001 МГЭ Дополнение 81, ремонт №220 II квартал 2026 года и Коэффициенты к ТСН-2001.13-2 Дополнение 47 №65 II квартал 2026 года
A22: № п/п | B22: Шифр расценки и коды ресурсов | C22: Наименование работ и затрат | D22: Ед. изм. | E22: Кол-во единиц | F22: Цена на ед. изм., руб. | G22: Попра- вочные коэффи- циенты | H22: Коэффи- циенты зимних удорожа- ний | I22: Всего в ценах на январь 2000 года, руб. | J22: Коэффи- циенты (индек- сы) пере- счета, нормы НР и СП | K22: ВСЕГО затрат в текущем уровне цен, руб.
A23: 1 | B23: 2 | C23: 3 | D23: 4 | E23: 5 | F23: 6 | G23: 7 | H23: 8 | I23: 9 | J23: 10 | K23: 11
A24: Раздел: АРМ СОТС
A25: 1 | B25: 4.11-7-2 Поправка: Гл.12.Прил.8.п.8. 3_12.00.01.11.001 | C25: Установка аппарата настольного массой до 0,03 т | D25: 1 ШТ. | E25: 1
C26: ЗП | F26: 34.55 | G26: 1,2 | H26: 1 | I26: 41.46 | J26: 57.05 | K26: 2365.29
C27: ЭМ | F27: 26.59 | G27: 1,2 | H27: 1 | I27: 31.91 | J27: 17.45 | K27: 556.83
C28: в т.ч. ЗПМ | F28: 4.04 | G28: 1,2 | H28: 1 | I28: 4.85 | J28: 57.05 | K28: 276.69
C29: НР от ФОТ | D29: % | E29: 90 | I29: 41.68 | J29: 90 | K29: 2377.78
C30: СП от ФОТ | D30: % | E30: 46 | I30: 21.3 | J30: 46 | K30: 1215.31
C31: ЗТР | D31: чел-ч | E31: 3.09 | G31: 1,2 | H31: 1 | I31: 3.71
C32: ВСЕГО работ по позиции: | H32: 136.35 | J32: 6515.21
C33: ВСЕГО по позиции: | H33: 136.35 | J33: 6515.21
A35: 2 | B35: Прайс-лист | C35: ОБОРУДОВАНИЕ: Автоматизированное рабочее место в комплекте (процессор, монитор, клавиатура, мышь) 9 679,34 = [85 420 / 1,22 / 7,54] + 3% Трансп + 1,2% Заг.скл | D35: ШТ | E35: 1 | F35: 9679.34 | H35: 1 | I35: 9679.34 | J35: 7.54 | K35: 72982.22
C36: ВСЕГО по позиции: | H36: 9679.34 | J36: 72982.22
A38: 3 | B38: Прайс-лист | C38: ОБОРУДОВАНИЕ: Операционная система 1 654,39 = [14 600 / 1,22 / 7,54] + 3% Трансп + 1,2% Заг.скл | D38: ШТ | E38: 1 | F38: 1654.39 | H38: 1 | I38: 1654.39 | J38: 7.54 | K38: 12474.1
C39: ВСЕГО по позиции: | H39: 1654.39 | J39: 12474.1
A41: 4 | B41: 4.10-173-2 Поправка: Гл.12.Прил.8.п.8. 3_12.00.01.11.001 | C41: Монтаж блока бесперебойного питания (ББП) в диспетчерской | D41: 1 ШТ. | E41: 1
C42: ЗП | F42: 40.17 | G42: 1,2 | H42: 1 | I42: 48.2 | J42: 57.05 | K42: 2749.81
C43: МР | F43: 2.34 | H43: 1 | I43: 2.34 | J43: 9.91 | K43: 23.19
C44: НР от ФОТ | D44: % | E44: 90 | I44: 43.38 | J44: 90 | K44: 2474.83
C45: СП от ФОТ | D45: % | E45: 46 | I45: 22.17 | J45: 46 | K45: 1264.91
C46: ЗТР | D46: чел-ч | E46: 3.18 | G46: 1,2 | H46: 1 | I46: 3.82
C47: ВСЕГО работ по позиции: | H47: 116.09 | J47: 6512.74
C48: ВСЕГО по позиции: | H48: 116.09 | J48: 6512.74
A50: 5 | B50: Прайс-лист | C50: ОБОРУДОВАНИЕ: Источник бесперебойного питания, 600Вт 1 083,57 = [9 562,46 / 1,22 / 7,54] + 3% Трансп + 1,2% Заг.скл | D50: ШТ | E50: 1 | F50: 1083.57 | H50: 1 | I50: 1083.57 | J50: 7.54 | K50: 8170.12
...

Sheet ЛС 02-01-11
J2: Форма № 4б
A3: =ССРСС!A11 -> Выполнение работ по капитальному ремонту здания в Басманном районе ЦАО города Москвы
A4: (наименование стройки и/или объекта)
A6: ЛОКАЛЬНАЯ СМЕТА № 02-01-11
A8: Радиотрансляционная сеть
A9: (наименование работ и затрат)
I12: В базисном уровне цен | J12: В текущем уровне цен
E13: Сметная стоимость | I13: 179.2 | J13: 1463.47 | K13: тыс.руб.
E14: Строительные работы | I14: 0.7 | J14: 7.09 | K14: тыс.руб.
E15: Работы по монтажу оборудования | I15: 5.1 | J15: 146.82 | K15: тыс.руб.
E16: Оборудование | I16: 173.4 | J16: 1309.56 | K16: тыс.руб.
E17: Средства на оплату труда | I17: 0.9 | J17: 51.54 | K17: тыс.руб.
E18: Затраты труда | I18: 71.6 | K18: чел.-ч.
A20: Составлен(а) по ТСН-2001 с учетом Дополнения №: 81
A21: № и период сборника коэффициентов (индексов) пересчета: Коэффициенты к ТСН-2001 МГЭ Дополнение 81, ремонт №220 II квартал 2026 года и Коэффициенты к ТСН-2001.13-2 Дополнение 47 №65 II квартал 2026 года
A22: № п/п | B22: Шифр расценки и коды ресурсов | C22: Наименование работ и затрат | D22: Ед. изм. | E22: Кол-во единиц | F22: Цена на ед. изм., руб. | G22: Попра- вочные коэффи- циенты | H22: Коэффи- циенты зимних удорожа- ний | I22: Всего в ценах на январь 2000 года, руб. | J22: Коэффи- циенты (индек- сы) пере- счета, нормы НР и СП | K22: ВСЕГО затрат в текущем уровне цен, руб.
A23: 1 | B23: 2 | C23: 3 | D23: 4 | E23: 5 | F23: 6 | G23: 7 | H23: 8 | I23: 9 | J23: 10 | K23: 11
A24: Раздел: Оборудование
A25: 1 | B25: 4.10-75-1 Поправка: Гл.12.Прил.8.п.8. 3_12.00.01.11.001 | C25: Установка шкафа или статива (стойки) радиотрансляционных узлов массой до 100 кг | D25: 1 ШТ. | E25: 1
C26: ЗП | F26: 164.06 | G26: 1,2 | H26: 1 | I26: 196.87 | J26: 57.05 | K26: 11231.43
C27: НР от ФОТ | D27: % | E27: 95 | I27: 187.03 | J27: 95 | K27: 10669.86
C28: СП от ФОТ | D28: % | E28: 53 | I28: 104.34 | J28: 53 | K28: 5952.66
C29: ЗТР | D29: чел-ч | E29: 13 | G29: 1,2 | H29: 1 | I29: 15.6
C30: ВСЕГО работ по позиции: | H30: 488.24 | J30: 27853.95
C31: ВСЕГО по позиции: | H31: 488.24 | J31: 27853.95
A33: 2 | B33: Прайс-лист | C33: ОБОРУДОВАНИЕ: Устройство подачи программ вещания 56 920,27 = [502 320 / 1,22 / 7,54] + 3% Трансп + 1,2% Заг.скл | D33: ШТ | E33: 1 | F33: 56920.27 | H33: 1 | I33: 56920.27 | J33: 7.54 | K33: 429178.84
C34: ВСЕГО по позиции: | H34: 56920.27 | J34: 429178.84
A36: 3 | B36: 4.11-12-1 Поправка: Гл.12.Прил.8.п.8. 3_12.00.01.11.001 | C36: Установка съемных и выдвижных блоков (модулей, ячеек, ТЭЗ) массой до 5 кг | D36: 1 ШТ. | E36: 1
C37: ЗП | F37: 11.65 | G37: 1,2 | H37: 1 | I37: 13.98 | J37: 57.05 | K37: 797.56
C38: ЭМ | F38: 0.5 | G38: 1,2 | H38: 1 | I38: 0.6 | J38: 17.4 | K38: 10.44
C39: в т.ч. ЗПМ | F39: 0.08 | G39: 1,2 | H39: 1 | I39: 0.1 | J39: 57.05 | K39: 5.71
C40: НР от ФОТ | D40: % | E40: 90 | I40: 12.67 | J40: 90 | K40: 722.94
C41: СП от ФОТ | D41: % | E41: 46 | I41: 6.48 | J41: 46 | K41: 369.5
C42: ЗТР | D42: чел-ч | E42: 1.03 | G42: 1,2 | H42: 1 | I42: 1.24
C43: ВСЕГО работ по позиции: | H43: 33.73 | J43: 1900.44
C44: ВСЕГО по позиции: | H44: 33.73 | J44: 1900.44
A46: 4 | B46: Прайс-лист | C46: ОБОРУДОВАНИЕ:_x000D_ Модуль для приема потокового вещания «Радио Москвы» 3 467,44 = [30 600 / 1,22 / 7,54] + 3% Трансп + 1,2% Заг.скл | D46: ШТ | E46: 1 | F46: 3467.44 | H46: 1 | I46: 3467.44 | J46: 7.54 | K46: 26144.5
C47: ВСЕГО по позиции: | H47: 3467.44 | J47: 26144.5
A49: 5 | B49: 4.10-75-1 Поправка: Гл.12.Прил.8.п.8. 3_12.00.01.11.001 | C49: Установка шкафа или статива (стойки) радиотрансляционных узлов массой до 100 кг | D49: 1 ШТ. | E49: 1
C50: ЗП | F50: 164.06 | G50: 1,2 | H50: 1 | I50: 196.87 | J50: 57.05 | K50: 11231.43
...

Sheet ЛС 02-01-12
J2: Форма № 4б
A3: =ССРСС!A11 -> Выполнение работ по капитальному ремонту здания в Басманном районе ЦАО города Москвы
A4: (наименование стройки и/или объекта)
A6: ЛОКАЛЬНАЯ СМЕТА № 02-01-12
A8: Система кабельного телевидения
A9: (наименование работ и затрат)
I12: В базисном уровне цен | J12: В текущем уровне цен
E13: Сметная стоимость | I13: 26.58 | J13: 331.72 | K13: тыс.руб.
E14: Строительные работы | I14: 0.6 | J14: 6.12 | K14: тыс.руб.
E15: Работы по монтажу оборудования | I15: 15.03 | J15: 243.07 | K15: тыс.руб.
E16: Оборудование | I16: 10.95 | J16: 82.53 | K16: тыс.руб.
E17: Средства на оплату труда | I17: 1.59 | J17: 90.48 | K17: тыс.руб.
E18: Затраты труда | I18: 111.37 | K18: чел.-ч.
A20: Составлен(а) по ТСН-2001 с учетом Дополнения №: 81
A21: № и период сборника коэффициентов (индексов) пересчета: Коэффициенты к ТСН-2001 МГЭ Дополнение 81, строительство №220 II квартал 2026 года и Коэффициенты к ТСН-2001.13-2 Дополнение 47 №65 II квартал 2026 года
A22: № п/п | B22: Шифр расценки и коды ресурсов | C22: Наименование работ и затрат | D22: Ед. изм. | E22: Кол-во единиц | F22: Цена на ед. изм., руб. | G22: Попра- вочные коэффи- циенты | H22: Коэффи- циенты зимних удорожа- ний | I22: Всего в ценах на январь 2000 года, руб. | J22: Коэффи- циенты (индек- сы) пере- счета, нормы НР и СП | K22: ВСЕГО затрат в текущем уровне цен, руб.
A23: 1 | B23: 2 | C23: 3 | D23: 4 | E23: 5 | F23: 6 | G23: 7 | H23: 8 | I23: 9 | J23: 10 | K23: 11
A24: Раздел: Монтажные работы
A25: 1 | B25: 4.10-136-5 Поправка: Гл.12.Прил.8.п.8. 3_12.00.01.11.001 | C25: Монтаж базового блока головной станции настенного типа | D25: 1 ШТ. | E25: 1
C26: ЗП | F26: 111.68 | G26: 1,2 | H26: 1 | I26: 134.02 | J26: 57.05 | K26: 7645.84
C27: МР | F27: 0.3 | H27: 1 | I27: 0.3 | J27: 7.37 | K27: 2.21
C28: НР от ФОТ | D28: % | E28: 95 | I28: 127.32 | J28: 95 | K28: 7263.55
C29: СП от ФОТ | D29: % | E29: 53 | I29: 71.03 | J29: 53 | K29: 4052.3
C30: ЗТР | D30: чел-ч | E30: 8 | G30: 1,2 | H30: 1 | I30: 9.6
C31: ВСЕГО работ по позиции: | H31: 332.67 | J31: 18963.9
C32: ВСЕГО по позиции: | H32: 332.67 | J32: 18963.9
A34: 2 | B34: Прайс-лист | C34: ОБОРУДОВАНИЕ: Головная станция 9 396,45 = [82 923,38 / 1,22 / 7,54] + 3% Трансп + 1,2% Заг.скл | D34: ШТ | E34: 1 | F34: 9396.45 | H34: 1 | I34: 9396.45 | J34: 7.54 | K34: 70849.23
C35: ВСЕГО по позиции: | H35: 9396.45 | J35: 70849.23
A37: 3 | B37: 4.10-136-3 Поправка: Гл.12.Прил.8.п.8. 3_12.00.01.11.001 | C37: Монтаж антенного ТВ усилителя на мачте (без измерений) без повала мачты | D37: 1 ШТ. | E37: 1
C38: ЗП | F38: 25.78 | G38: 1,2 | H38: 1 | I38: 30.94 | J38: 57.05 | K38: 1765.13
C39: МР | F39: 0.18 | H39: 1 | I39: 0.18 | J39: 5.61 | K39: 1.01
C40: НР от ФОТ | D40: % | E40: 95 | I40: 29.39 | J40: 95 | K40: 1676.87
C41: СП от ФОТ | D41: % | E41: 53 | I41: 16.4 | J41: 53 | K41: 935.52
C42: ЗТР | D42: чел-ч | E42: 1.9 | G42: 1,2 | H42: 1 | I42: 2.28
C43: ВСЕГО работ по позиции: | H43: 76.91 | J43: 4378.53
C44: ВСЕГО по позиции: | H44: 76.91 | J44: 4378.53
A46: 4 | B46: Прайс-лист | C46: ОБОРУДОВАНИЕ: Антенный усилитель с БП 12В, Ку= 14/27 237,96 = [2 100 / 1,22 / 7,54] + 3% Трансп + 1,2% Заг.скл | D46: ШТ | E46: 1 | F46: 237.96 | H46: 1 | I46: 237.96 | J46: 7.54 | K46: 1794.22
C47: ВСЕГО по позиции: | H47: 237.96 | J47: 1794.22
A49: 5 | B49: 4.10-136-1 Поправка: Гл.12.Прил.8.п.8. 3_12.00.01.11.001 | C49: Монтаж коробки телевизионной (ответвители, разветвители магистральные, домовые, абонентские), УСС, БФТК | D49: 1 ШТ. | E49: 1
C50: ЗП | F50: 11.02 | G50: 1,2 | H50: 1 | I50: 13.22 | J50: 57.05 | K50: 754.2
...

Sheet ЛС 02-01-13
J2: Форма № 4б
A3: =ССРСС!A11 -> Выполнение работ по капитальному ремонту здания в Басманном районе ЦАО города Москвы
A4: (наименование стройки и/или объекта)
A6: ЛОКАЛЬНАЯ СМЕТА № 02-01-13
A8: Структурированная кабельная сеть
A9: (наименование работ и затрат)
I12: В базисном уровне цен | J12: В текущем уровне цен
E13: Сметная стоимость | I13: 398.57 | J13: 3916.82 | K13: тыс.руб.
E14: Строительные работы | I14: 34.13 | J14: 347.43 | K14: тыс.руб.
E15: Работы по монтажу оборудования | I15: 52.48 | J15: 1217.23 | K15: тыс.руб.
E16: Оборудование | I16: 311.96 | J16: 2352.16 | K16: тыс.руб.
E17: Средства на оплату труда | I17: 7.81 | J17: 445.71 | K17: тыс.руб.
E18: Затраты труда | I18: 632.84 | K18: чел.-ч.
A20: Составлен(а) по ТСН-2001 с учетом Дополнения №: 81
A21: № и период сборника коэффициентов (индексов) пересчета: Коэффициенты к ТСН-2001 МГЭ Дополнение 81, строительство №220 II квартал 2026 года и Коэффициенты к ТСН-2001.13-2 Дополнение 47 №65 II квартал 2026 года
A22: № п/п | B22: Шифр расценки и коды ресурсов | C22: Наименование работ и затрат | D22: Ед. изм. | E22: Кол-во единиц | F22: Цена на ед. изм., руб. | G22: Попра- вочные коэффи- циенты | H22: Коэффи- циенты зимних удорожа- ний | I22: Всего в ценах на январь 2000 года, руб. | J22: Коэффи- циенты (индек- сы) пере- счета, нормы НР и СП | K22: ВСЕГО затрат в текущем уровне цен, руб.
A23: 1 | B23: 2 | C23: 3 | D23: 4 | E23: 5 | F23: 6 | G23: 7 | H23: 8 | I23: 9 | J23: 10 | K23: 11
A24: Раздел: Оборудование
A25: 1 | B25: 4.10-32-1 Поправка: Гл.12.Прил.8.п.8. 3_12.00.01.11.001 | C25: Монтаж стойки, полустойки, каркаса стойки или шкафа массой до 100 кг | D25: 1 ШТ. | E25: 1
C26: ЗП | F26: 91.68 | G26: 1,2 | H26: 1 | I26: 110.02 | J26: 57.05 | K26: 6276.64
C27: ЭМ | F27: 38.92 | G27: 1,2 | H27: 1 | I27: 46.7 | J27: 16.34 | K27: 763.08
C28: в т.ч. ЗПМ | F28: 4.16 | G28: 1,2 | H28: 1 | I28: 4.99 | J28: 57.05 | K28: 284.68
C29: МР | F29: 3.92 | H29: 1 | I29: 3.92 | J29: 7.06 | K29: 27.68
C30: НР от ФОТ | D30: % | E30: 90 | I30: 103.51 | J30: 90 | K30: 5905.19
C31: СП от ФОТ | D31: % | E31: 46 | I31: 52.9 | J31: 46 | K31: 3018.21
C32: ЗТР | D32: чел-ч | E32: 8.2 | G32: 1,2 | H32: 1 | I32: 9.84
C33: ВСЕГО работ по позиции: | H33: 317.05 | J33: 15990.8
C34: ВСЕГО по позиции: | H34: 317.05 | J34: 15990.8
A36: 2 | B36: Прайс-лист | C36: ОБОРУДОВАНИЕ: Телекоммуникационный шкаф типоразмера 19", 42U шир.800мм, гл.800мм, 3 каб.ввода передняя дверь стеклянная,задняя дв.перфорированные,1-створчатые, боковые панели,шнуры заземления,ножки-4поворотных колеса,белый 20 560,41 = [181 445 / 1,22 / 7,54] + 3% Трансп + 1,2% Заг.скл | D36: ШТ | E36: 1 | F36: 20560.41 | H36: 1 | I36: 20560.41 | J36: 7.54 | K36: 155025.49
C37: ВСЕГО по позиции: | H37: 20560.41 | J37: 155025.49
A39: 3 | B39: 4.10-1-13 Поправка: Гл.12.Прил.8.п.8. 3_12.00.01.11.001 | C39: Установка рамки со штифтами на винтах и гайках с шайбами | D39: 1 рамка | E39: 1
C40: ЗП | F40: 1.45 | G40: 1,2 | H40: 1 | I40: 1.74 | J40: 57.05 | K40: 99.27
C41: НР от ФОТ | D41: % | E41: 90 | I41: 1.57 | J41: 90 | K41: 89.34
C42: СП от ФОТ | D42: % | E42: 46 | I42: 0.8 | J42: 46 | K42: 45.66
C43: ЗТР | D43: чел-ч | E43: 0.13 | G43: 1,2 | H43: 1 | I43: 0.16
C44: ВСЕГО работ по позиции: | H44: 4.11 | J44: 234.27
C45: ВСЕГО по позиции: | H45: 4.11 | J45: 234.27
A47: 4 | B47: Прайс-лист | C47: ОБОРУДОВАНИЕ: Вертикальный органайзер с крышкой , 2шт 4 839,73 = [42 710,46 / 1,22 / 7,54] + 3% Трансп + 1,2% Заг.скл | D47: КОМПЛ | E47: 1 | F47: 4839.73 | H47: 1 | I47: 4839.73 | J47: 7.54 | K47: 36491.56
C48: ВСЕГО по позиции: | H48: 4839.73 | J48: 36491.56
A50: 5 | B50: Прайс-лист | C50: ОБОРУДОВАНИЕ: Шина заземления 19" (500мм), 20 точек,5х15мм 494,16 = [4 361 / 1,22 / 7,54] + 3% Трансп + 1,2% Заг.скл | D50: ШТ | E50: 1 | F50: 494.16 | H50: 1 | I50: 494.16 | J50: 7.54 | K50: 3725.97
...

Sheet ЛС 02-01-14
J2: Форма № 4б
A3: =ССРСС!A11 -> Выполнение работ по капитальному ремонту здания в Басманном районе ЦАО города Москвы
A4: (наименование стройки и/или объекта)
A6: ЛОКАЛЬНАЯ СМЕТА № 02-01-14
A8: Система охранного теленаблюдения
A9: (наименование работ и затрат)
I12: В базисном уровне цен | J12: В текущем уровне цен
E13: Сметная стоимость | I13: 116.6 | J13: 1565.76 | K13: тыс.руб.
E14: Строительные работы | I14: 12.38 | J14: 126.04 | K14: тыс.руб.
E15: Работы по монтажу оборудования | I15: 28.89 | J15: 872.27 | K15: тыс.руб.
E16: Оборудование | I16: 75.33 | J16: 567.45 | K16: тыс.руб.
E17: Средства на оплату труда | I17: 5.68 | J17: 324.17 | K17: тыс.руб.
E18: Затраты труда | I18: 456.19 | K18: чел.-ч.
A20: Составлен(а) по ТСН-2001 с учетом Дополнения №: 81
A21: № и период сборника коэффициентов (индексов) пересчета: Коэффициенты к ТСН-2001 МГЭ Дополнение 81, строительство №220 II квартал 2026 года и Коэффициенты к ТСН-2001.13-2 Дополнение 47 №65 II квартал 2026 года
A22: № п/п | B22: Шифр расценки и коды ресурсов | C22: Наименование работ и затрат | D22: Ед. изм. | E22: Кол-во единиц | F22: Цена на ед. изм., руб. | G22: Попра- вочные коэффи- циенты | H22: Коэффи- циенты зимних удорожа- ний | I22: Всего в ценах на январь 2000 года, руб. | J22: Коэффи- циенты (индек- сы) пере- счета, нормы НР и СП | K22: ВСЕГО затрат в текущем уровне цен, руб.
A23: 1 | B23: 2 | C23: 3 | D23: 4 | E23: 5 | F23: 6 | G23: 7 | H23: 8 | I23: 9 | J23: 10 | K23: 11
A24: Раздел: Оборудование
A25: 1 | B25: 4.10-174-2 Поправка: Гл.12.Прил.8.п.8. 3_12.00.01.11.001 | C25: Монтаж наружной камеры видеонаблюдения | D25: 10 шт. | E25: 0.5
C26: Объем: 0,5=5/10
C27: ЗП | F27: 401.27 | G27: 1,2 | H27: 1 | I27: 240.76 | J27: 57.05 | K27: 13735.36
C28: ЭМ | F28: 2.36 | G28: 1,2 | H28: 1 | I28: 1.42 | J28: 11.47 | K28: 16.29
C29: в т.ч. ЗПМ | F29: 0.13 | G29: 1,2 | H29: 1 | I29: 0.08 | J29: 57.05 | K29: 4.56
C30: МР | F30: 42.51 | H30: 1 | I30: 21.26 | J30: 1.84 | K30: 39.12
C31: НР от ФОТ | D31: % | E31: 90 | I31: 216.76 | J31: 90 | K31: 12365.93
C32: СП от ФОТ | D32: % | E32: 46 | I32: 110.79 | J32: 46 | K32: 6320.36
C33: ЗТР | D33: чел-ч | E33: 25.33 | G33: 1,2 | H33: 1 | I33: 15.2
C34: ВСЕГО работ по позиции: | H34: 590.99 | J34: 32477.06
C35: ВСЕГО по позиции: | H35: 590.99 | J35: 32477.06
A37: 2 | B37: Прайс-лист | C37: ОБОРУДОВАНИЕ: Цилиндрическая IP-видеокамера с фиксированным объективом IP 4 Мп; размер матрицы 1/2.9"; встроенный микрофон; Дальность ИК подсветки 80м; режим "день/ночь"; PoE 7 Вт; -40 ~ +60°C, (2/8-12) 1 236,60 = [10 913 / 1,22 / 7,54] + 3% Трансп + 1,2% Заг.скл | D37: ШТ | E37: 5 | F37: 1236.6 | H37: 1 | I37: 6183 | J37: 7.54 | K37: 46619.82
C38: ВСЕГО по позиции: | H38: 6183 | J38: 46619.82
A40: 3 | B40: 4.10-136-1 Поправка: Гл.12.Прил.8.п.8. 3_12.00.01.11.001 | C40: Монтаж коробки телевизионной (ответвители, разветвители магистральные, домовые, абонентские), УСС, БФТК | D40: 1 ШТ. | E40: 5
C41: ЗП | F41: 11.02 | G41: 1,2 | H41: 1 | I41: 66.12 | J41: 57.05 | K41: 3772.15
C42: МР | F42: 0.3 | H42: 1 | I42: 1.5 | J42: 7.37 | K42: 11.06
C43: НР от ФОТ | D43: % | E43: 95 | I43: 62.81 | J43: 95 | K43: 3583.54
C44: СП от ФОТ | D44: % | E44: 53 | I44: 35.04 | J44: 53 | K44: 1999.24
C45: ЗТР | D45: чел-ч | E45: 0.8 | G45: 1,2 | H45: 1 | I45: 4.8
C46: ВСЕГО работ по позиции: | H46: 165.47 | J46: 9365.99
C47: ВСЕГО по позиции: | H47: 165.47 | J47: 9365.99
A49: 4 | B49: Прайс-лист | C49: ОБОРУДОВАНИЕ: Устройство грозозащиты 326,34 = [2 880 / 1,22 / 7,54] + 3% Трансп + 1,2% Заг.скл | D49: ШТ | E49: 5 | F49: 326.34 | H49: 1 | I49: 1631.7 | J49: 7.54 | K49: 12303.02
...

Sheet ЛС 02-01-15
A1: Smeta.RU (495) 974-1589
J2: Форма № 4б
A3: =ССРСС!A11 -> Выполнение работ по капитальному ремонту здания в Басманном районе ЦАО города Москвы
A4: (наименование стройки и/или объекта)
